<?xml version="1.0" ?>
<robot name="synus_robot">

  <link name="base_link">
    <visual>
      <geometry>
        <box size="0.16 0.16 0.16"/>
      </geometry>
      <origin rpy="0 0 0" xyz="0 0 0.085"/>
      <material name="white">
        <color rgba="1 1 1 1"/>
      </material>
    </visual>
  </link>

  <link name="lwheel">
    <visual>
      <geometry>
        <cylinder length="0.008" radius="0.046"/>
      </geometry>
      <origin rpy="0 1.57 0" xyz="0 0 0"/>
      <!-- 1.57=3.14/2  -->
      <material name="black">
        <color rgba="0 0 0 1"/>
      </material>
    </visual>
  </link>

  <joint name="base_to_lwheel" type="continuous">
    <parent link="base_link"/>
    <child link="lwheel"/>
    <origin xyz="0 0.115 0.046" rpy="0 0 1.5708"/>
    <axis xyz="1 0 0" />
  </joint>

  <link name="rwheel">
    <visual>
      <geometry>
        <cylinder length="0.008" radius="0.046"/>
      </geometry>
      <origin rpy="0 1.57 0" xyz="0 0 0"/>
      <material name="black">
        <color rgba="0 0 0 1"/>
      </material>
    </visual>
  </link>

  <joint name="base_to_rwheel" type="continuous">
    <parent link="base_link"/>
    <child link="rwheel"/>
    <origin xyz="0 -0.115 0.046" rpy="0 0 -1.5708"/>
    <axis xyz="1 0 0" />
  </joint>

  <link name="laser">
    <visual>
      <geometry>
        <box size="0.015 0.045 0.015"/>
      </geometry>
      <origin rpy="0 0 0" xyz="0.022 0 0.015"/>
      <material name="black">
        <color rgba="0 0 0 1"/>
      </material>
    </visual>
  </link>

  <joint name="base_to_laser" type="fixed">
    <parent link="base_link"/>
    <child link="laser"/>
    <origin xyz="0 0 0.22" rpy="0 0 0"/>
  </joint>

</robot>
